<?xml version="1.0"?>

<robot name="pioneer3dx" xmlns:xacro="http://ros.org/wiki/xacro">
<xacro:property name="ns" value="$(arg ns)/" />
  <xacro:include filename="$(find pioneer_simulator)/urdf/pioneer3dx_wheel_ns.xacro"/>
  <xacro:include filename="$(find pioneer_simulator)/urdf/pioneer3dx_sensor_ns.xacro"/>

  <xacro:p3dx_wheel suffix="left" parent="{ns}base_link" reflect="1"/>
  <xacro:p3dx_wheel suffix="right" parent="{ns}base_link" reflect="-1"/>

  <!-- Chassis description -->
  <link name="${ns}base_link">
	<!-- CHECK THESE VALUES. THEY MAY BE COMPLETELY WRONG. -->
	<inertial>
      <mass value="20.0"/>
	  <origin xyz="-0.045 0 0.148"/>
	  <inertia ixx="0.3338" ixy="0.0" ixz="0.0"
			   iyy="0.4783" iyz="0.0"
			   izz="0.3338"/>
	</inertial>
	<!-- The base visual is fine. Just the inertial is questionable.-->
	<visual>
	  <origin xyz="-0.045 0 0.148" rpy="0 0 0"/>
	  <geometry name="pioneer_geom">
		<mesh filename="package://p2os_urdf/meshes/p3dx_meshes/chassis.stl"/>
	  </geometry>
	  <material name="ChassisRed">
		<color rgba="0.851 0.0 0.0 1.0"/>
	  </material>
	</visual>
	
	<collision>
          <origin xyz="-0.045 0 0.78" rpy="0 0 0"/>
          <!--xyz="-0.045 0 0.148""/-->
	  <geometry>
        <box size="0.4 0.28 1.00"/>
                <!--box size="0.4 0.28 0.17"/-->
	  </geometry>
	</collision>
  </link>
  <gazebo reference="${ns}base_link">
	<material value="Gazebo/Red"/>
  </gazebo>

  <link name="${ns}top_plate">
	<inertial>
      <mass value="0.1"/>
	  <origin xyz="0 0 0"/>
	  <inertia ixx="1" ixy="0" ixz="0"
			   iyy="1" iyz="0"
 			   izz="1"/>
	</inertial>
	<visual>
	  <origin xyz="0 0 0" rpy="0 0 0"/>
	  <geometry name="pioneer_geom">
		<mesh filename="package://p2os_urdf/meshes/p3dx_meshes/top.stl"/>
	  </geometry>
	  <material name="TopBlack">
		<color rgba="0.038 0.038 0.038 1.0"/>
	  </material>
	</visual>
  </link>
  <gazebo reference="${ns}top_plate">
	<material value="Gazebo/Black"/>
  </gazebo>

  <joint name="${ns}base_top_joint" type="fixed">
	<origin xyz="-0.045 0 0.24" rpy="0 0 0"/>
        <parent link="${ns}base_link"/>
        <child link="${ns}top_plate"/>
  </joint>

  <!-- Swivel -->
  <link name="${ns}swivel">
	<inertial>
	  <mass value="0.1"/>	
	  <origin xyz="0 0 0"/>
	  <inertia ixx="0.01" ixy="0" ixz="0"
			   iyy="0.01" iyz="0" izz="0.01"/>
  	</inertial>
	<visual>
	  <origin xyz="0 0 0" rpy="0 0 0"/>
	  <geometry name="pioneer_geom">
		<mesh filename="package://p2os_urdf/meshes/p3dx_meshes/swivel.stl"/>
	  </geometry>
	  <material name="swivel">
		<color rgba="0.5 0.5 0.5 1"/>
	  </material>
	</visual>
  </link>
  <gazebo reference="${ns}swivel">
	<material value="Gazebo/Black"/>
  </gazebo>

  <joint name="${ns}base_swivel_joint" type="continuous">
	<origin xyz="-0.185 0 0.055" rpy="0 0 0"/>
	<axis xyz="0 0 1"/>
    <limit effort="100" velocity="100" k_velocity="0" />
    <joint_properties damping="0.0" friction="0.0" />
        <parent link="${ns}base_link"/>
        <child link="${ns}swivel"/>
  </joint>

  <!-- Center Wheel + Hubcap -->
  <link name="${ns}center_hubcap">
    <inertial>
      <mass value="0.5"/>
	  <origin xyz="0 0 0"/>
	  <inertia ixx="0.012411765597" ixy="-0.000711733678" ixz="0.00050272983"
			   iyy="0.015218160428" iyz="-0.000004273467" izz="0.011763977943"/>
  	</inertial>
	<visual>
	  <origin xyz="0 0 0" rpy="0 0 0"/>
	  <geometry name="pioneer_geom">
		<mesh filename="package://p2os_urdf/meshes/p3dx_meshes/center_hubcap.stl"/>
	  </geometry>
	  <material name="swivel">
		<color rgba="0.5 0.5 0.5 1"/>
	  </material>
	</visual>
  </link>
  <gazebo reference="${ns}center_hubcap">
        <material value="Gazebo/Black"/>
  </gazebo>

  <link name="${ns}center_wheel">
	<inertial>
      <mass value="0.5"/>
	  <origin xyz="0 0 0"/>
	  <inertia ixx="0.012411765597" ixy="-0.000711733678" ixz="0.00050272983"
			   iyy="0.015218160428" iyz="-0.000004273467" izz="0.011763977943"/>
  	</inertial>
    <visual>
	  <origin xyz="0 0 0" rpy="0 0 0"/>
	  <geometry name="pioneer_geom">
		<mesh filename="package://p2os_urdf/meshes/p3dx_meshes/center_wheel.stl"/>
	  </geometry>
	  <material name="WheelBlack">
		<color rgba="0.117 0.117 0.117 1"/>
	  </material>
	</visual>
	<collision>
	  <origin xyz="0 0 0" rpy="${-3.1415927/2.0} 0 0"/>
	  <geometry>
		<cylinder radius="0.0375" length="0.0314"/>
	  </geometry>
	</collision>
  </link>
  <gazebo reference="${ns}center_wheel">
	<material value="Gazebo/Black"/>
  </gazebo>

  <joint name="${ns}swivel_hubcap_joint" type="continuous">
    <origin xyz="-0.026 0 -0.016" rpy="0 0 0"/>
    <axis xyz="0 1 0"/>
    <anchor xyz="0 0 0"/>
    <limit effort="100" velocity="100" k_velocity="0" />
    <joint_properties damping="0.0" friction="0.0" />
    <parent link="${ns}swivel"/>
    <child link="${ns}center_wheel"/>
  </joint>

  <joint name="${ns}center_wheel_joint" type="fixed">
	<origin xyz="-0.0035 0 -0.001" rpy="0 0 0"/>
    <parent link="${ns}center_wheel"/>
    <child link="${ns}center_hubcap"/>
  </joint>

  <!-- Front + Back Sonar -->
  <link name="${ns}front_sonar">
	<inertial>
	  <mass value="0.0001"/>	
	  <origin xyz="0 0 0"/>
	  <inertia ixx="1" ixy="0" ixz="0"
			   iyy="1" iyz="0" izz="1"/>
	</inertial>
	<visual>
	  <origin xyz="0 0 0" rpy="0 0 0"/>
	  <geometry name="pioneer_geom">
		<mesh filename="package://p2os_urdf/meshes/p3dx_meshes/front_sonar.stl"/>
	  </geometry>
	  <material name="SonarYellow">
		<color rgba="0.715 0.583 0.210 1.0"/>
	  </material>
	</visual>
  </link>
  <gazebo reference="${ns}front_sonar">
	<material value="Gazebo/Yellow"/>
  </gazebo>

  <joint name="${ns}base_front_joint" type="fixed">
	<origin xyz="-0.198 0 0.208" rpy="0 0 0"/>
        <parent link="${ns}base_link"/>
        <child link="${ns}front_sonar"/>
  </joint>

  <link name="${ns}back_sonar">
	<inertial>
	  <mass value="0.0001"/>	
	  <origin xyz="0 0 0"/>
	  <inertia ixx="1" ixy="0" ixz="0"
			   iyy="1" iyz="0" izz="1"/>
	</inertial>
	<visual>
	  <origin xyz="0 0 0" rpy="0 0 0"/>
	  <geometry name="pioneer_geom">
		<mesh filename="package://p2os_urdf/meshes/p3dx_meshes/back_sonar.stl"/>
	  </geometry>
	  <material name="SonarYellow">
		<color rgba="0.715 0.583 0.210 1.0"/>
	  </material>
	</visual>
  </link>
  <gazebo reference="${ns}back_sonar">
	<material value="Gazebo/Yellow"/>
  </gazebo>

  <joint name="${ns}base_back_joint" type="fixed">
	<origin xyz="0.109 0 0.209" rpy="0 0 0"/>
	<!-- <origin xyz="0 0 0" rpy="0 0 0"/> -->
        <parent link="${ns}base_link"/>
        <child link="${ns}back_sonar"/>
  </joint>

  <gazebo>
    <!-- Robot locomotion plugin -->
	<plugin name="differential_drive_controller" filename="libgazebo_ros_diff_drive.so">
      <legacyMode>false</legacyMode>
      <alwaysOn>true</alwaysOn>
	  <updateRate>100.0</updateRate>
          <leftJoint>${ns}base_left_wheel_joint</leftJoint>
      <rightJoint>${ns}base_right_wheel_joint</rightJoint>
      <wheelSeparation>0.32</wheelSeparation>
	  <wheelDiameter>0.18</wheelDiameter>
	  <wheelTorque>5</wheelTorque>
      <wheelAcceleration>0</wheelAcceleration>
      <robotNamespace>${ns}</robotNamespace>
          <commandTopic>${ns}cmd_vel</commandTopic>
          <odometryTopic>${ns}odom</odometryTopic>
      <odometrySource>ENCODER</odometrySource><!--Other option is World-->
          <odometryFrame>${ns}odom</odometryFrame>
      <robotBaseFrame>${ns}base_link</robotBaseFrame>
      <publishTf>1</publishTf>
     <!-- <publishOdomTF>true</publishOdomTF>-->
      <publishWheelTF>false</publishWheelTF>
      <publishWheelJointState>false</publishWheelJointState>
      <rosDebugLevel>Warn</rosDebugLevel>
	</plugin>

    <!-- Fake localization plugin -->
    <plugin name="ground_truth_odometry" filename="libgazebo_ros_p3d.so">
	  <alwaysOn>true</alwaysOn>
	  <updateRate>100.0</updateRate>
          <bodyName>${ns}base_link</bodyName>
          <topicName>${ns}base_pose_ground_truth</topicName>
      <gaussianNoise>0.00</gaussianNoise>
          <frameName>map</frameName>
      <!-- initialize odometry for fake localization -->
          <xyzOffsets>0 0 0</xyzOffsets>
      <rpyOffsets>0 0 0</rpyOffsets>
	</plugin>

  </gazebo>

</robot>
